Workbook

Sheet instructions
A1: 2026 Men's Tournament Monte Carlo Model Workbook
A2: 1) teams tab now contains true KenPom NetRtg values in column E.
A3: 2) AP-based scoring uses Week 19 AP rankings and round win multipliers (not round reached points).
A4: 3) First Four placeholder rows remain blank for AP/base points and kenpom because the winner determines the value.
A5: 4) torvik and evanmia columns are still open for later fill.
A6: • Teams tab includes AP rank, base points, and per-round win-point columns
A7: • First Four placeholder rows leave AP/base points blank because scoring depends on which team wins the play-in
A9: How this pool scores
A10: • Pick 10 teams
A11: • Base points from Week 19 AP buckets:
A12: - AP 1-5 = 1 point
A13: - AP 6-10 = 2 points
... A23: Updated torvik from uploaded T-Rank PDF using AdjOE - AdjDE and evanmia from uploaded EvanMiya PDF using Relative Rating.

Sheet params
A1: parameter | B1: value | C1: notes
A2: weight_kenpom_z | B2: 0.4 | C2: Must sum to 1. Used for composite_rating in teams tab.
A3: weight_torvik_z | B3: 0.35 | C3: Must sum to 1. Used for composite_rating in teams tab.
A4: weight_evanmia_z | B4: 0.25 | C4: Must sum to 1. Used for composite_rating in teams tab.
A5: weights_sum_check | B5: =SUM(B2:B4) | C5: Should equal 1.0
A6: logistic_k | B6: 1 | C6: Controls how rating differences map to win probabilities. Calibrate later.
A7: mean_kenpom | B7: 16.841324 | C7: Auto-calculated from teams ratings
A8: stdevp_kenpom | B8: 12.142459 | C8: Auto-calculated from teams ratings
A9: mean_torvik | B9: 0.789725 | C9: Auto-calculated from teams ratings
A10: stdevp_torvik | B10: 0.19780729 | C10: Auto-calculated from teams ratings
A11: mean_evanmia | B11: 15.183824 | C11: Auto-calculated from teams ratings
A12: stdevp_evanmia | B12: 10.826895 | C12: Auto-calculated from teams ratings
A14: ap_poll_week_for_scoring | B14: Week 19 | C14: Pool scoring uses Week 19 AP Top 25 (Mar 9-15, 2026).

Sheet teams
A1: team_id | B1: team_name | C1: seed | D1: region | E1: kenpom | F1: torvik | G1: evanmia | H1: kenpom_z | I1: torvik_z | J1: evanmia_z | K1: composite_rating | L1: ap_rank_week19 | M1: base_points | N1: r1_win_points | O1: r2_win_points | P1: sweet16_win_points | Q1: elite8_win_points | R1: final4_win_points | S1: title_win_points
A2: NOTE: KenPom uses 2026 NetRtg. Torvik now uses 2026 BARTHAG (not AdjOE-AdjDE). EvanMiya uses 2026 Relative Rating. z-scores and composite below are precomputed so there are no formula compatibility issues.
A3: DATA STARTS ON ROW 4. Composite rating uses weighted z-scores to standardize different scales before combining.
A4: DUKE | B4: Duke | C4: 1 | D4: East | E4: 38.9 | F4: 0.9813 | G4: 34.8 | H4: 1.8166565 | I4: 0.96849312 | J4: 1.8118008 | K4: 1.5185854 | L4: 1 | M4: =IF($L4="",6,IF($L4<=5,1,IF($L4<=10,2,IF($L4<=15,3,IF($L4<=20,4,IF($L4<=25,5,6)))))) | N4: =IF($M4="","",$M4) | O4: =IF($M4="","",$M4*2) | P4: =IF($M4="","",$M4*3) | Q4: =IF($M4="","",$M4*4) | R4: =IF($M4="","",$M4*5) | S4: =IF($M4="","",$M4*6)
A5: SIENA | B5: Siena | C5: 16 | D5: East | E5: -2.1 | F5: 0.4548 | G5: -0.1 | H5: -1.5599249 | I5: -1.6931883 | J5: -1.4116535 | K5: -1.5694992 | M5: =IF($L5="",6,IF($L5<=5,1,IF($L5<=10,2,IF($L5<=15,3,IF($L5<=20,4,IF($L5<=25,5,6)))))) | N5: =IF($M5="","",$M5) | O5: =IF($M5="","",$M5*2) | P5: =IF($M5="","",$M5*3) | Q5: =IF($M5="","",$M5*4) | R5: =IF($M5="","",$M5*5) | S5: =IF($M5="","",$M5*6)
A6: OHST | B6: Ohio State | C6: 8 | D6: East | E6: 22.24 | F6: 0.9172 | G6: 21.2 | H6: 0.44461148 | I6: 0.64444035 | J6: 0.55566962 | K6: 0.54231612 | M6: =IF($L6="",6,IF($L6<=5,1,IF($L6<=10,2,IF($L6<=15,3,IF($L6<=20,4,IF($L6<=25,5,6)))))) | N6: =IF($M6="","",$M6) | O6: =IF($M6="","",$M6*2) | P6: =IF($M6="","",$M6*3) | Q6: =IF($M6="","",$M6*4) | R6: =IF($M6="","",$M6*5) | S6: =IF($M6="","",$M6*6)
A7: TCU | B7: TCU | C7: 9 | D7: East | E7: 17.59 | F7: 0.8367 | G7: 16 | H7: 0.061657733 | I7: 0.23747861 | J7: 0.07538417 | K7: 0.12662665 | M7: =IF($L7="",6,IF($L7<=5,1,IF($L7<=10,2,IF($L7<=15,3,IF($L7<=20,4,IF($L7<=25,5,6)))))) | N7: =IF($M7="","",$M7) | O7: =IF($M7="","",$M7*2) | P7: =IF($M7="","",$M7*3) | Q7: =IF($M7="","",$M7*4) | R7: =IF($M7="","",$M7*5) | S7: =IF($M7="","",$M7*6)
A8: SJU | B8: St. John's | C8: 5 | D8: East | E8: 25.91 | F8: 0.9415 | G8: 25.5 | H8: 0.74685669 | I8: 0.76728719 | J8: 0.95282874 | K8: 0.80550037 | L8: 13 | M8: =IF($L8="",6,IF($L8<=5,1,IF($L8<=10,2,IF($L8<=15,3,IF($L8<=20,4,IF($L8<=25,5,6)))))) | N8: =IF($M8="","",$M8) | O8: =IF($M8="","",$M8*2) | P8: =IF($M8="","",$M8*3) | Q8: =IF($M8="","",$M8*4) | R8: =IF($M8="","",$M8*5) | S8: =IF($M8="","",$M8*6)
A9: UNI | B9: Northern Iowa | C9: 12 | D9: East | E9: 11.81 | F9: 0.7752 | G9: 10.6 | H9: -0.41435789 | I9: -0.073430054 | J9: -0.4233738 | K9: -0.29728712 | M9: =IF($L9="",6,IF($L9<=5,1,IF($L9<=10,2,IF($L9<=15,3,IF($L9<=20,4,IF($L9<=25,5,6)))))) | N9: =IF($M9="","",$M9) | O9: =IF($M9="","",$M9*2) | P9: =IF($M9="","",$M9*3) | Q9: =IF($M9="","",$M9*4) | R9: =IF($M9="","",$M9*5) | S9: =IF($M9="","",$M9*6)
A10: KU | B10: Kansas | C10: 4 | D10: East | E10: 24.44 | F10: 0.9278 | G10: 21.9 | H10: 0.62579389 | I10: 0.69802786 | J10: 0.62032343 | K10: 0.64970816 | L10: 14 | M10: =IF($L10="",6,IF($L10<=5,1,IF($L10<=10,2,IF($L10<=15,3,IF($L10<=20,4,IF($L10<=25,5,6)))))) | N10: =IF($M10="","",$M10) | O10: =IF($M10="","",$M10*2) | P10: =IF($M10="","",$M10*3) | Q10: =IF($M10="","",$M10*4) | R10: =IF($M10="","",$M10*5) | S10: =IF($M10="","",$M10*6)
A11: CBU | B11: California Baptist | C11: 13 | D11: East | E11: 5.99 | F11: 0.689 | G11: 3.7 | H11: -0.89366773 | I11: -0.50920772 | J11: -1.0606756 | K11: -0.80085871 | M11: =IF($L11="",6,IF($L11<=5,1,IF($L11<=10,2,IF($L11<=15,3,IF($L11<=20,4,IF($L11<=25,5,6)))))) | N11: =IF($M11="","",$M11) | O11: =IF($M11="","",$M11*2) | P11: =IF($M11="","",$M11*3) | Q11: =IF($M11="","",$M11*4) | R11: =IF($M11="","",$M11*5) | S11: =IF($M11="","",$M11*6)
A12: LOU | B12: Louisville | C12: 6 | D12: East | E12: 25.42 | F12: 0.9364 | G12: 21.8 | H12: 0.70650242 | I12: 0.74150452 | J12: 0.61108717 | K12: 0.69489934 | L12: 24 | M12: =IF($L12="",6,IF($L12<=5,1,IF($L12<=10,2,IF($L12<=15,3,IF($L12<=20,4,IF($L12<=25,5,6)))))) | N12: =IF($M12="","",$M12) | O12: =IF($M12="","",$M12*2) | P12: =IF($M12="","",$M12*3) | Q12: =IF($M12="","",$M12*4) | R12: =IF($M12="","",$M12*5) | S12: =IF($M12="","",$M12*6)
A13: USF | B13: South Florida | C13: 11 | D13: East | E13: 16.39 | F13: 0.8356 | G13: 15.8 | H13: -0.03716904 | I13: 0.23191764 | J13: 0.056911652 | K13: 0.080531471 | M13: =IF($L13="",6,IF($L13<=5,1,IF($L13<=10,2,IF($L13<=15,3,IF($L13<=20,4,IF($L13<=25,5,6)))))) | N13: =IF($M13="","",$M13) | O13: =IF($M13="","",$M13*2) | P13: =IF($M13="","",$M13*3) | Q13: =IF($M13="","",$M13*4) | R13: =IF($M13="","",$M13*5) | S13: =IF($M13="","",$M13*6)
A14: MSU | B14: Michigan State | C14: 3 | D14: East | E14: 28.31 | F14: 0.9438 | G14: 24.6 | H14: 0.94451023 | I14: 0.77891466 | J14: 0.86970241 | K14: 0.86784983 | L14: 8 | M14: =IF($L14="",6,IF($L14<=5,1,IF($L14<=10,2,IF($L14<=15,3,IF($L14<=20,4,IF($L14<=25,5,6)))))) | N14: =IF($M14="","",$M14) | O14: =IF($M14="","",$M14*2) | P14: =IF($M14="","",$M14*3) | Q14: =IF($M14="","",$M14*4) | R14: =IF($M14="","",$M14*5) | S14: =IF($M14="","",$M14*6)
A15: NDSU | B15: North Dakota State | C15: 14 | D15: East | E15: 5.13 | F15: 0.6391 | G15: 4.2 | H15: -0.96449359 | I15: -0.76147345 | J15: -1.0144943 | K15: -0.90593673 | M15: =IF($L15="",6,IF($L15<=5,1,IF($L15<=10,2,IF($L15<=15,3,IF($L15<=20,4,IF($L15<=25,5,6)))))) | N15: =IF($M15="","",$M15) | O15: =IF($M15="","",$M15*2) | P15: =IF($M15="","",$M15*3) | Q15: =IF($M15="","",$M15*4) | R15: =IF($M15="","",$M15*5) | S15: =IF($M15="","",$M15*6)
A16: UCLA | B16: UCLA | C16: 7 | D16: East | E16: 21.67 | F16: 0.9107 | G16: 20.3 | H16: 0.39766876 | I16: 0.61158008 | J16: 0.47254329 | K16: 0.49125636 | M16: =IF($L16="",6,IF($L16<=5,1,IF($L16<=10,2,IF($L16<=15,3,IF($L16<=20,4,IF($L16<=25,5,6)))))) | N16: =IF($M16="","",$M16) | O16: =IF($M16="","",$M16*2) | P16: =IF($M16="","",$M16*3) | Q16: =IF($M16="","",$M16*4) | R16: =IF($M16="","",$M16*5) | S16: =IF($M16="","",$M16*6)
A17: UCF | B17: UCF | C17: 10 | D17: East | E17: 15.04 | F17: 0.8116 | G17: 11.3 | H17: -0.14834916 | I17: 0.11058743 | J17: -0.35871999 | K17: -0.11031406 | M17: =IF($L17="",6,IF($L17<=5,1,IF($L17<=10,2,IF($L17<=15,3,IF($L17<=20,4,IF($L17<=25,5,6)))))) | N17: =IF($M17="","",$M17) | O17: =IF($M17="","",$M17*2) | P17: =IF($M17="","",$M17*3) | Q17: =IF($M17="","",$M17*4) | R17: =IF($M17="","",$M17*5) | S17: =IF($M17="","",$M17*6)
A18: CONN | B18: UConn | C18: 2 | D18: East | E18: 27.87 | F18: 0.9517 | G18: 29 | H18: 0.90827375 | I18: 0.81885252 | J18: 1.2760978 | K18: 0.96893233 | L18: 6 | M18: =IF($L18="",6,IF($L18<=5,1,IF($L18<=10,2,IF($L18<=15,3,IF($L18<=20,4,IF($L18<=25,5,6)))))) | N18: =IF($M18="","",$M18) | O18: =IF($M18="","",$M18*2) | P18: =IF($M18="","",$M18*3) | Q18: =IF($M18="","",$M18*4) | R18: =IF($M18="","",$M18*5) | S18: =IF($M18="","",$M18*6)
A19: FUR | B19: Furman | C19: 15 | D19: East | E19: -1.98 | F19: 0.4442 | G19: 0.9 | H19: -1.5500422 | I19: -1.7467759 | J19: -1.3192909 | K19: -1.5612112 | M19: =IF($L19="",6,IF($L19<=5,1,IF($L19<=10,2,IF($L19<=15,3,IF($L19<=20,4,IF($L19<=25,5,6)))))) | N19: =IF($M19="","",$M19) | O19: =IF($M19="","",$M19*2) | P19: =IF($M19="","",$M19*3) | Q19: =IF($M19="","",$M19*4) | R19: =IF($M19="","",$M19*5) | S19: =IF($M19="","",$M19*6)
A20: ARIZ | B20: Arizona | C20: 1 | D20: West | E20: 37.66 | F20: 0.9776 | G20: 32 | H20: 1.7145355 | I20: 0.94978804 | J20: 1.5531855 | K20: 1.4065364 | L20: 2 | M20: =IF($L20="",6,IF($L20<=5,1,IF($L20<=10,2,IF($L20<=15,3,IF($L20<=20,4,IF($L20<=25,5,6)))))) | N20: =IF($M20="","",$M20) | O20: =IF($M20="","",$M20*2) | P20: =IF($M20="","",$M20*3) | Q20: =IF($M20="","",$M20*4) | R20: =IF($M20="","",$M20*5) | S20: =IF($M20="","",$M20*6)
A21: LIU | B21: Long Island | C21: 16 | D21: West | E21: -3.95 | F21: 0.3404 | G21: -3.3 | H21: -1.7122828 | I21: -2.271529 | J21: -1.7072137 | K21: -1.9067517 | M21: =IF($L21="",6,IF($L21<=5,1,IF($L21<=10,2,IF($L21<=15,3,IF($L21<=20,4,IF($L21<=25,5,6)))))) | N21: =IF($M21="","",$M21) | O21: =IF($M21="","",$M21*2) | P21: =IF($M21="","",$M21*3) | Q21: =IF($M21="","",$M21*4) | R21: =IF($M21="","",$M21*5) | S21: =IF($M21="","",$M21*6)
A22: NOVA | B22: Villanova | C22: 8 | D22: West | E22: 19.97 | F22: 0.8803 | G22: 15 | H22: 0.25766416 | I22: 0.45789515 | J22: -0.016978417 | K22: 0.25908437 | M22: =IF($L22="",6,IF($L22<=5,1,IF($L22<=10,2,IF($L22<=15,3,IF($L22<=20,4,IF($L22<=25,5,6)))))) | N22: =IF($M22="","",$M22) | O22: =IF($M22="","",$M22*2) | P22: =IF($M22="","",$M22*3) | Q22: =IF($M22="","",$M22*4) | R22: =IF($M22="","",$M22*5) | S22: =IF($M22="","",$M22*6)
A23: USU | B23: Utah State | C23: 9 | D23: West | E23: 20.76 | F23: 0.8952 | G23: 17.6 | H23: 0.32272512 | I23: 0.53322099 | J23: 0.22316431 | K23: 0.37150847 | M23: =IF($L23="",6,IF($L23<=5,1,IF($L23<=10,2,IF($L23<=15,3,IF($L23<=20,4,IF($L23<=25,5,6)))))) | N23: =IF($M23="","",$M23) | O23: =IF($M23="","",$M23*2) | P23: =IF($M23="","",$M23*3) | Q23: =IF($M23="","",$M23*4) | R23: =IF($M23="","",$M23*5) | S23: =IF($M23="","",$M23*6)
A24: WIS | B24: Wisconsin | C24: 5 | D24: West | E24: 23.39 | F24: 0.9294 | G24: 21.7 | H24: 0.53932047 | I24: 0.70611654 | J24: 0.60185091 | K24: 0.6133317 | L24: 23 | M24: =IF($L24="",6,IF($L24<=5,1,IF($L24<=10,2,IF($L24<=15,3,IF($L24<=20,4,IF($L24<=25,5,6)))))) | N24: =IF($M24="","",$M24) | O24: =IF($M24="","",$M24*2) | P24: =IF($M24="","",$M24*3) | Q24: =IF($M24="","",$M24*4) | R24: =IF($M24="","",$M24*5) | S24: =IF($M24="","",$M24*6)
A25: HPU | B25: High Point | C25: 12 | D25: West | E25: 8.4 | F25: 0.6993 | G25: 8.6 | H25: -0.69519063 | I25: -0.45713684 | J25: -0.60809897 | K25: -0.59009889 | M25: =IF($L25="",6,IF($L25<=5,1,IF($L25<=10,2,IF($L25<=15,3,IF($L25<=20,4,IF($L25<=25,5,6)))))) | N25: =IF($M25="","",$M25) | O25: =IF($M25="","",$M25*2) | P25: =IF($M25="","",$M25*3) | Q25: =IF($M25="","",$M25*4) | R25: =IF($M25="","",$M25*5) | S25: =IF($M25="","",$M25*6)
A26: ARK | B26: Arkansas | C26: 4 | D26: West | E26: 26.05 | F26: 0.9337 | G26: 23.8 | H26: 0.75838648 | I26: 0.72785487 | J26: 0.79581234 | K26: 0.75705688 | L26: 17 | M26: =IF($L26="",6,IF($L26<=5,1,IF($L26<=10,2,IF($L26<=15,3,IF($L26<=20,4,IF($L26<=25,5,6)))))) | N26: =IF($M26="","",$M26) | O26: =IF($M26="","",$M26*2) | P26: =IF($M26="","",$M26*3) | Q26: =IF($M26="","",$M26*4) | R26: =IF($M26="","",$M26*5) | S26: =IF($M26="","",$M26*6)
A27: HAW | B27: Hawaiʻi | C27: 13 | D27: West | E27: 5.97 | F27: 0.6352 | G27: 3.3 | H27: -0.89531485 | I27: -0.78118961 | J27: -1.0976207 | K27: -0.90594747 | M27: =IF($L27="",6,IF($L27<=5,1,IF($L27<=10,2,IF($L27<=15,3,IF($L27<=20,4,IF($L27<=25,5,6)))))) | N27: =IF($M27="","",$M27) | O27: =IF($M27="","",$M27*2) | P27: =IF($M27="","",$M27*3) | Q27: =IF($M27="","",$M27*4) | R27: =IF($M27="","",$M27*5) | S27: =IF($M27="","",$M27*6)
A28: BYU | B28: BYU | C28: 6 | D28: West | E28: 23.25 | F28: 0.8866 | G28: 16.5 | H28: 0.52779068 | I28: 0.48974433 | J28: 0.12156546 | K28: 0.41291815 | M28: =IF($L28="",6,IF($L28<=5,1,IF($L28<=10,2,IF($L28<=15,3,IF($L28<=20,4,IF($L28<=25,5,6)))))) | N28: =IF($M28="","",$M28) | O28: =IF($M28="","",$M28*2) | P28: =IF($M28="","",$M28*3) | Q28: =IF($M28="","",$M28*4) | R28: =IF($M28="","",$M28*5) | S28: =IF($M28="","",$M28*6)
A29: SMU | B29: SMU | C29: 11 | D29: West | E29: 18.09 | F29: 0.8608 | G29: 16.6 | H29: 0.10283555 | I29: 0.35931436 | J29: 0.13080172 | K29: 0.19959468 | M29: =IF($L29="",6,IF($L29<=5,1,IF($L29<=10,2,IF($L29<=15,3,IF($L29<=20,4,IF($L29<=25,5,6)))))) | N29: =IF($M29="","",$M29) | O29: =IF($M29="","",$M29*2) | P29: =IF($M29="","",$M29*3) | Q29: =IF($M29="","",$M29*4) | R29: =IF($M29="","",$M29*5) | S29: =IF($M29="","",$M29*6)
A30: MIAOH | B30: Miami (OH) | C30: 11 | D30: West | E30: 8.26 | F30: 0.7175 | G30: 8.1 | H30: -0.70672042 | I30: -0.3651281 | J30: -0.65428026 | K30: -0.57405307 | L30: 20 | M30: =IF($L30="",6,IF($L30<=5,1,IF($L30<=10,2,IF($L30<=15,3,IF($L30<=20,4,IF($L30<=25,5,6)))))) | N30: =IF($M30="","",$M30) | O30: =IF($M30="","",$M30*2) | P30: =IF($M30="","",$M30*3) | Q30: =IF($M30="","",$M30*4) | R30: =IF($M30="","",$M30*5) | S30: =IF($M30="","",$M30*6)
A31: GONZ | B31: Gonzaga | C31: 3 | D31: West | E31: 28.1 | F31: 0.9446 | G31: 27.7 | H31: 0.92721555 | I31: 0.782959 | J31: 1.1560264 | K31: 0.93392848 | L31: 12 | M31: =IF($L31="",6,IF($L31<=5,1,IF($L31<=10,2,IF($L31<=15,3,IF($L31<=20,4,IF($L31<=25,5,6)))))) | N31: =IF($M31="","",$M31) | O31: =IF($M31="","",$M31*2) | P31: =IF($M31="","",$M31*3) | Q31: =IF($M31="","",$M31*4) | R31: =IF($M31="","",$M31*5) | S31: =IF($M31="","",$M31*6)
A32: KENN | B32: Kennesaw State | C32: 14 | D32: West | E32: 0.57 | F32: 0.5338 | G32: 1 | H32: -1.3400353 | I32: -1.2938097 | J32: -1.3100546 | K32: -1.3163612 | M32: =IF($L32="",6,IF($L32<=5,1,IF($L32<=10,2,IF($L32<=15,3,IF($L32<=20,4,IF($L32<=25,5,6)))))) | N32: =IF($M32="","",$M32) | O32: =IF($M32="","",$M32*2) | P32: =IF($M32="","",$M32*3) | Q32: =IF($M32="","",$M32*4) | R32: =IF($M32="","",$M32*5) | S32: =IF($M32="","",$M32*6)
A33: MIA | B33: Miami (FL) | C33: 7 | D33: West | E33: 20.68 | F33: 0.8844 | G33: 18.6 | H33: 0.31613667 | I33: 0.4786224 | J33: 0.31552689 | K33: 0.37285423 | M33: =IF($L33="",6,IF($L33<=5,1,IF($L33<=10,2,IF($L33<=15,3,IF($L33<=20,4,IF($L33<=25,5,6)))))) | N33: =IF($M33="","",$M33) | O33: =IF($M33="","",$M33*2) | P33: =IF($M33="","",$M33*3) | Q33: =IF($M33="","",$M33*4) | R33: =IF($M33="","",$M33*5) | S33: =IF($M33="","",$M33*6)
A34: MIZZ | B34: Missouri | C34: 10 | D34: West | E34: 15.39 | F34: 0.8515 | G34: 14.4 | H34: -0.11952468 | I34: 0.3122989 | J34: -0.072395968 | K34: 0.04339575 | M34: =IF($L34="",6,IF($L34<=5,1,IF($L34<=10,2,IF($L34<=15,3,IF($L34<=20,4,IF($L34<=25,5,6)))))) | N34: =IF($M34="","",$M34) | O34: =IF($M34="","",$M34*2) | P34: =IF($M34="","",$M34*3) | Q34: =IF($M34="","",$M34*4) | R34: =IF($M34="","",$M34*5) | S34: =IF($M34="","",$M34*6)
A35: PUR | B35: Purdue | C35: 2 | D35: West | E35: 31.2 | F35: 0.9636 | G35: 30.3 | H35: 1.182518 | I35: 0.87901209 | J35: 1.3961692 | K35: 1.1297037 | L35: 18 | M35: =IF($L35="",6,IF($L35<=5,1,IF($L35<=10,2,IF($L35<=15,3,IF($L35<=20,4,IF($L35<=25,5,6)))))) | N35: =IF($M35="","",$M35) | O35: =IF($M35="","",$M35*2) | P35: =IF($M35="","",$M35*3) | Q35: =IF($M35="","",$M35*4) | R35: =IF($M35="","",$M35*5) | S35: =IF($M35="","",$M35*6)
A36: QUE | B36: Queens | C36: 15 | D36: West | E36: -1.44 | F36: 0.4399 | G36: -2.1 | H36: -1.5055702 | I36: -1.7685142 | J36: -1.5963786 | K36: -1.6203027 | M36: =IF($L36="",6,IF($L36<=5,1,IF($L36<=10,2,IF($L36<=15,3,IF($L36<=20,4,IF($L36<=25,5,6)))))) | N36: =IF($M36="","",$M36) | O36: =IF($M36="","",$M36*2) | P36: =IF($M36="","",$M36*3) | Q36: =IF($M36="","",$M36*4) | R36: =IF($M36="","",$M36*5) | S36: =IF($M36="","",$M36*6)
A37: UF | B37: Florida | C37: 1 | D37: South | E37: 33.79 | F37: 0.9732 | G37: 31.4 | H37: 1.3958192 | I37: 0.92754417 | J37: 1.497768 | K37: 1.2574101 | L37: 4 | M37: =IF($L37="",6,IF($L37<=5,1,IF($L37<=10,2,IF($L37<=15,3,IF($L37<=20,4,IF($L37<=25,5,6)))))) | N37: =IF($M37="","",$M37) | O37: =IF($M37="","",$M37*2) | P37: =IF($M37="","",$M37*3) | Q37: =IF($M37="","",$M37*4) | R37: =IF($M37="","",$M37*5) | S37: =IF($M37="","",$M37*6)
A38: HOW | B38: Howard | C38: 16 | D38: South | E38: -3.19 | F38: 0.4251 | G38: -1.1 | H38: -1.6496925 | I38: -1.8433345 | J38: -1.5040161 | K38: -1.6810481 | M38: =IF($L38="",6,IF($L38<=5,1,IF($L38<=10,2,IF($L38<=15,3,IF($L38<=20,4,IF($L38<=25,5,6)))))) | N38: =IF($M38="","",$M38) | O38: =IF($M38="","",$M38*2) | P38: =IF($M38="","",$M38*3) | Q38: =IF($M38="","",$M38*4) | R38: =IF($M38="","",$M38*5) | S38: =IF($M38="","",$M38*6)
A39: UMBC | B39: UMBC | C39: 16 | D39: South | E39: -1.67 | F39: 0.4563 | G39: -0.1 | H39: -1.524512 | I39: -1.6856052 | J39: -1.4116535 | K39: -1.55268 | M39: =IF($L39="",6,IF($L39<=5,1,IF($L39<=10,2,IF($L39<=15,3,IF($L39<=20,4,IF($L39<=25,5,6)))))) | N39: =IF($M39="","",$M39) | O39: =IF($M39="","",$M39*2) | P39: =IF($M39="","",$M39*3) | Q39: =IF($M39="","",$M39*4) | R39: =IF($M39="","",$M39*5) | S39: =IF($M39="","",$M39*6)
A40: CLEM | B40: Clemson | C40: 8 | D40: South | E40: 19.24 | F40: 0.8921 | G40: 16.6 | H40: 0.19754454 | I40: 0.51754917 | J40: 0.13080172 | K40: 0.29286046 | M40: =IF($L40="",6,IF($L40<=5,1,IF($L40<=10,2,IF($L40<=15,3,IF($L40<=20,4,IF($L40<=25,5,6)))))) | N40: =IF($M40="","",$M40) | O40: =IF($M40="","",$M40*2) | P40: =IF($M40="","",$M40*3) | Q40: =IF($M40="","",$M40*4) | R40: =IF($M40="","",$M40*5) | S40: =IF($M40="","",$M40*6)
...

Sheet first_round_matchups
A1: game_id | B1: round_num | C1: region | D1: slot | E1: team1_id | F1: team2_id | G1: team1_name | H1: team1_seed | I1: team2_name | J1: team2_seed
A2: R64_E_01 | B2: 64 | C2: East | D2: 1 | E2: DUKE | F2: SIENA | G2: =IF($E2="","",VLOOKUP($E2,teams!$A$4:$K$75,2,FALSE)) | H2: =IF($E2="","",VLOOKUP($E2,teams!$A$4:$K$75,3,FALSE)) | I2: =IF($F2="","",VLOOKUP($F2,teams!$A$4:$K$75,2,FALSE)) | J2: =IF($F2="","",VLOOKUP($F2,teams!$A$4:$K$75,3,FALSE))
A3: R64_E_02 | B3: 64 | C3: East | D3: 2 | E3: OHST | F3: TCU | G3: =IF($E3="","",VLOOKUP($E3,teams!$A$4:$K$75,2,FALSE)) | H3: =IF($E3="","",VLOOKUP($E3,teams!$A$4:$K$75,3,FALSE)) | I3: =IF($F3="","",VLOOKUP($F3,teams!$A$4:$K$75,2,FALSE)) | J3: =IF($F3="","",VLOOKUP($F3,teams!$A$4:$K$75,3,FALSE))
A4: R64_E_03 | B4: 64 | C4: East | D4: 3 | E4: SJU | F4: UNI | G4: =IF($E4="","",VLOOKUP($E4,teams!$A$4:$K$75,2,FALSE)) | H4: =IF($E4="","",VLOOKUP($E4,teams!$A$4:$K$75,3,FALSE)) | I4: =IF($F4="","",VLOOKUP($F4,teams!$A$4:$K$75,2,FALSE)) | J4: =IF($F4="","",VLOOKUP($F4,teams!$A$4:$K$75,3,FALSE))
A5: R64_E_04 | B5: 64 | C5: East | D5: 4 | E5: KU | F5: CBU | G5: =IF($E5="","",VLOOKUP($E5,teams!$A$4:$K$75,2,FALSE)) | H5: =IF($E5="","",VLOOKUP($E5,teams!$A$4:$K$75,3,FALSE)) | I5: =IF($F5="","",VLOOKUP($F5,teams!$A$4:$K$75,2,FALSE)) | J5: =IF($F5="","",VLOOKUP($F5,teams!$A$4:$K$75,3,FALSE))
A6: R64_E_05 | B6: 64 | C6: East | D6: 5 | E6: LOU | F6: USF | G6: =IF($E6="","",VLOOKUP($E6,teams!$A$4:$K$75,2,FALSE)) | H6: =IF($E6="","",VLOOKUP($E6,teams!$A$4:$K$75,3,FALSE)) | I6: =IF($F6="","",VLOOKUP($F6,teams!$A$4:$K$75,2,FALSE)) | J6: =IF($F6="","",VLOOKUP($F6,teams!$A$4:$K$75,3,FALSE))
A7: R64_E_06 | B7: 64 | C7: East | D7: 6 | E7: MSU | F7: NDSU | G7: =IF($E7="","",VLOOKUP($E7,teams!$A$4:$K$75,2,FALSE)) | H7: =IF($E7="","",VLOOKUP($E7,teams!$A$4:$K$75,3,FALSE)) | I7: =IF($F7="","",VLOOKUP($F7,teams!$A$4:$K$75,2,FALSE)) | J7: =IF($F7="","",VLOOKUP($F7,teams!$A$4:$K$75,3,FALSE))
A8: R64_E_07 | B8: 64 | C8: East | D8: 7 | E8: UCLA | F8: UCF | G8: =IF($E8="","",VLOOKUP($E8,teams!$A$4:$K$75,2,FALSE)) | H8: =IF($E8="","",VLOOKUP($E8,teams!$A$4:$K$75,3,FALSE)) | I8: =IF($F8="","",VLOOKUP($F8,teams!$A$4:$K$75,2,FALSE)) | J8: =IF($F8="","",VLOOKUP($F8,teams!$A$4:$K$75,3,FALSE))
A9: R64_E_08 | B9: 64 | C9: East | D9: 8 | E9: CONN | F9: FUR | G9: =IF($E9="","",VLOOKUP($E9,teams!$A$4:$K$75,2,FALSE)) | H9: =IF($E9="","",VLOOKUP($E9,teams!$A$4:$K$75,3,FALSE)) | I9: =IF($F9="","",VLOOKUP($F9,teams!$A$4:$K$75,2,FALSE)) | J9: =IF($F9="","",VLOOKUP($F9,teams!$A$4:$K$75,3,FALSE))
A10: R64_W_01 | B10: 64 | C10: West | D10: 1 | E10: ARIZ | F10: LIU | G10: =IF($E10="","",VLOOKUP($E10,teams!$A$4:$K$75,2,FALSE)) | H10: =IF($E10="","",VLOOKUP($E10,teams!$A$4:$K$75,3,FALSE)) | I10: =IF($F10="","",VLOOKUP($F10,teams!$A$4:$K$75,2,FALSE)) | J10: =IF($F10="","",VLOOKUP($F10,teams!$A$4:$K$75,3,FALSE))
A11: R64_W_02 | B11: 64 | C11: West | D11: 2 | E11: NOVA | F11: USU | G11: =IF($E11="","",VLOOKUP($E11,teams!$A$4:$K$75,2,FALSE)) | H11: =IF($E11="","",VLOOKUP($E11,teams!$A$4:$K$75,3,FALSE)) | I11: =IF($F11="","",VLOOKUP($F11,teams!$A$4:$K$75,2,FALSE)) | J11: =IF($F11="","",VLOOKUP($F11,teams!$A$4:$K$75,3,FALSE))
A12: R64_W_03 | B12: 64 | C12: West | D12: 3 | E12: WIS | F12: HPU | G12: =IF($E12="","",VLOOKUP($E12,teams!$A$4:$K$75,2,FALSE)) | H12: =IF($E12="","",VLOOKUP($E12,teams!$A$4:$K$75,3,FALSE)) | I12: =IF($F12="","",VLOOKUP($F12,teams!$A$4:$K$75,2,FALSE)) | J12: =IF($F12="","",VLOOKUP($F12,teams!$A$4:$K$75,3,FALSE))
A13: R64_W_04 | B13: 64 | C13: West | D13: 4 | E13: ARK | F13: HAW | G13: =IF($E13="","",VLOOKUP($E13,teams!$A$4:$K$75,2,FALSE)) | H13: =IF($E13="","",VLOOKUP($E13,teams!$A$4:$K$75,3,FALSE)) | I13: =IF($F13="","",VLOOKUP($F13,teams!$A$4:$K$75,2,FALSE)) | J13: =IF($F13="","",VLOOKUP($F13,teams!$A$4:$K$75,3,FALSE))
... A33: R64_M_08 | B33: 64 | C33: Midwest | D33: 8 | E33: ISU | F33: TNST | G33: =IF($E33="","",VLOOKUP($E33,teams!$A$4:$K$75,2,FALSE)) | H33: =IF($E33="","",VLOOKUP($E33,teams!$A$4:$K$75,3,FALSE)) | I33: =IF($F33="","",VLOOKUP($F33,teams!$A$4:$K$75,2,FALSE)) | J33: =IF($F33="","",VLOOKUP($F33,teams!$A$4:$K$75,3,FALSE))

Sheet scoring_rules
A1: round_name | B1: round_code | C1: win_multiplier | D1: notes
A2: Round 1 | B2: 64 | C2: 1 | D2: Win Round of 64 game
A3: Round 2 | B3: 32 | C3: 2 | D3: Win Round of 32 game
A4: Sweet 16 | B4: 16 | C4: 3 | D4: Win Sweet 16 game
A5: Elite 8 | B5: 8 | C5: 4 | D5: Win Elite 8 game
A6: Final Four | B6: 4 | C6: 5 | D6: Win national semifinal
A7: Championship | B7: 2 | C7: 6 | D7: Win national title game
A9: Scoring basis | B9: Week 19 AP rankings | C9: Mar 9-15, 2026 | D9: Base points come from AP buckets; unranked = 6; First Four placeholder values depend on the winner.

Sheet historical_games
A1: season | B1: game_date | C1: team_a_id | D1: team_b_id | E1: team_a_score | F1: team_b_score | G1: team_a_win
A2: Optional: fill to calibrate k (logistic_k) using historical results.

Sheet first_four_matchups
A1: game_id | B1: region_target | C1: winner_placeholder_id | D1: seed_line | E1: team1_id | F1: team2_id | G1: team1_name | H1: team1_seed | I1: team2_name | J1: team2_seed
A2: FF_W_11 | B2: West | C2: FF_W_11 | D2: 11 | E2: SMU | F2: MIAOH | G2: =VLOOKUP(E2,teams!$A$4:$K$75,2,FALSE) | H2: =VLOOKUP(E2,teams!$A$4:$K$75,3,FALSE) | I2: =VLOOKUP(F2,teams!$A$4:$K$75,2,FALSE) | J2: =VLOOKUP(F2,teams!$A$4:$K$75,3,FALSE)
A3: FF_S_16 | B3: South | C3: FF_S_16 | D3: 16 | E3: HOW | F3: UMBC | G3: =VLOOKUP(E3,teams!$A$4:$K$75,2,FALSE) | H3: =VLOOKUP(E3,teams!$A$4:$K$75,3,FALSE) | I3: =VLOOKUP(F3,teams!$A$4:$K$75,2,FALSE) | J3: =VLOOKUP(F3,teams!$A$4:$K$75,3,FALSE)
A4: FF_M_11 | B4: Midwest | C4: FF_M_11 | D4: 11 | E4: NCSU | F4: TEX | G4: =VLOOKUP(E4,teams!$A$4:$K$75,2,FALSE) | H4: =VLOOKUP(E4,teams!$A$4:$K$75,3,FALSE) | I4: =VLOOKUP(F4,teams!$A$4:$K$75,2,FALSE) | J4: =VLOOKUP(F4,teams!$A$4:$K$75,3,FALSE)
A5: FF_M_16 | B5: Midwest | C5: FF_M_16 | D5: 16 | E5: LEH | F5: PVAM | G5: =VLOOKUP(E5,teams!$A$4:$K$75,2,FALSE) | H5: =VLOOKUP(E5,teams!$A$4:$K$75,3,FALSE) | I5: =VLOOKUP(F5,teams!$A$4:$K$75,2,FALSE) | J5: =VLOOKUP(F5,teams!$A$4:$K$75,3,FALSE)

Sheet sources
A1: source_name | B1: url | C1: notes
A2: KenPom 2026 ratings | B2: https://kenpom.com/index.php | C2: NetRtg values used for teams tab kenpom column; data through games of Sunday, March 15, 2026.
A3: Week 19 AP poll reference | B3: https://www.warrennolan.com/basketball/2026/polls/week/19 | C3: Used for ap_rank_week19 / base_points scoring buckets.
A4: 2026 NCAA bracket | B4: https://www.ncaa.com/news/basketball-men/mml-official-bracket/2026-03-17/2026-ncaa-tournament-printable-bracket-schedule-march-madness | C4: Bracket structure / field.
A5: Torvik PDF | B5: Uploaded PDF: T-Rank - Customizable College Basketball Tempo Free Stats - T-Rank.pdf | C5: torvik column uses AdjOE - AdjDE from 2026 T-Rank table
A6: EvanMiya PDF | B6: Uploaded PDF: EvanMiya CBB Analytics - College Basketball Team, Player, and Lineup Metrics.pdf | C6: evanmia column uses Relative Rating from 2025-26 team ratings table
